[2024-07-15T16:30:11.447+0000] {local_task_job_runner.py:120} INFO - ::group::Pre task execution logs
[2024-07-15T16:30:11.525+0000] {taskinstance.py:2076} INFO - Dependencies all met for dep_context=non-requeueable deps ti=<TaskInstance: Postgres_dag.insert_into_table manual__2024-07-15T16:11:52.260980+00:00 [queued]>
[2024-07-15T16:30:11.537+0000] {taskinstance.py:2076} INFO - Dependencies all met for dep_context=requeueable deps ti=<TaskInstance: Postgres_dag.insert_into_table manual__2024-07-15T16:11:52.260980+00:00 [queued]>
[2024-07-15T16:30:11.538+0000] {taskinstance.py:2306} INFO - Starting attempt 10 of 10
[2024-07-15T16:30:11.656+0000] {taskinstance.py:2330} INFO - Executing <Task(PostgresOperator): insert_into_table> on 2024-07-15 16:11:52.260980+00:00
[2024-07-15T16:30:11.676+0000] {logging_mixin.py:188} WARNING - /home/***/.local/lib/python3.12/site-packages/***/task/task_runner/standard_task_runner.py:61 DeprecationWarning: This process (pid=2603) is multi-threaded, use of fork() may lead to deadlocks in the child.
[2024-07-15T16:30:11.690+0000] {standard_task_runner.py:63} INFO - Started process 2610 to run task
[2024-07-15T16:30:11.693+0000] {standard_task_runner.py:90} INFO - Running: ['***', 'tasks', 'run', 'Postgres_dag', 'insert_into_table', 'manual__2024-07-15T16:11:52.260980+00:00', '--job-id', '160', '--raw', '--subdir', 'DAGS_FOLDER/dag_with_postgres.py', '--cfg-path', '/tmp/tmp5j5x5ylt']
[2024-07-15T16:30:11.705+0000] {standard_task_runner.py:91} INFO - Job 160: Subtask insert_into_table
[2024-07-15T16:30:11.957+0000] {task_command.py:426} INFO - Running <TaskInstance: Postgres_dag.insert_into_table manual__2024-07-15T16:11:52.260980+00:00 [running]> on host 32f997017b5a
[2024-07-15T16:30:12.797+0000] {taskinstance.py:2648} INFO - Exporting env vars: AIRFLOW_CTX_DAG_OWNER='Rayzo' AIRFLOW_CTX_DAG_ID='Postgres_dag' AIRFLOW_CTX_TASK_ID='insert_into_table' AIRFLOW_CTX_EXECUTION_DATE='2024-07-15T16:11:52.260980+00:00' AIRFLOW_CTX_TRY_NUMBER='10' AIRFLOW_CTX_DAG_RUN_ID='manual__2024-07-15T16:11:52.260980+00:00'
[2024-07-15T16:30:12.823+0000] {taskinstance.py:430} INFO - ::endgroup::
[2024-07-15T16:30:12.981+0000] {sql.py:276} INFO - Executing:  
        insert into drag_runs(dt,dag_id) values('2024-07-15', 'Postgres_dag')
        
[2024-07-15T16:30:13.097+0000] {base.py:84} INFO - Using connection ID 'Postgres_con' for task execution.
[2024-07-15T16:30:13.246+0000] {base.py:84} INFO - Using connection ID 'Postgres_con' for task execution.
[2024-07-15T16:30:13.500+0000] {sql.py:487} INFO - Running statement:  
        insert into drag_runs(dt,dag_id) values('2024-07-15', 'Postgres_dag')
        , parameters: None
[2024-07-15T16:30:13.607+0000] {taskinstance.py:441} INFO - ::group::Post task execution logs
[2024-07-15T16:30:13.625+0000] {taskinstance.py:2905} ERROR - Task failed with exception
Traceback (most recent call last):
  File "/home/airflow/.local/lib/python3.12/site-packages/airflow/models/taskinstance.py", line 465, in _execute_task
    result = _execute_callable(context=context, **execute_callable_kwargs)
             ^^^^^^^^^^^^^^^^^^^^^^^^^^^^^^^^^^^^^^^^^^^^^^^^^^^^^^^^^^^^^
  File "/home/airflow/.local/lib/python3.12/site-packages/airflow/models/taskinstance.py", line 432, in _execute_callable
    return execute_callable(context=context, **execute_callable_kwargs)
           ^^^^^^^^^^^^^^^^^^^^^^^^^^^^^^^^^^^^^^^^^^^^^^^^^^^^^^^^^^^^
  File "/home/airflow/.local/lib/python3.12/site-packages/airflow/models/baseoperator.py", line 401, in wrapper
    return func(self, *args, **kwargs)
           ^^^^^^^^^^^^^^^^^^^^^^^^^^^
  File "/home/airflow/.local/lib/python3.12/site-packages/airflow/providers/common/sql/operators/sql.py", line 282, in execute
    output = hook.run(
             ^^^^^^^^^
  File "/home/airflow/.local/lib/python3.12/site-packages/airflow/providers/common/sql/hooks/sql.py", line 435, in run
    self._run_command(cur, sql_statement, parameters)
  File "/home/airflow/.local/lib/python3.12/site-packages/airflow/providers/common/sql/hooks/sql.py", line 492, in _run_command
    cur.execute(sql_statement)
psycopg2.errors.UniqueViolation: duplicate key value violates unique constraint "drag_runs_pkey"
DETAIL:  Key (dt, dag_id)=(2024-07-15, Postgres_dag) already exists.

[2024-07-15T16:30:13.712+0000] {taskinstance.py:1206} INFO - Marking task as FAILED. dag_id=Postgres_dag, task_id=insert_into_table, run_id=manual__2024-07-15T16:11:52.260980+00:00, execution_date=20240715T161152, start_date=20240715T163011, end_date=20240715T163013
[2024-07-15T16:30:13.911+0000] {standard_task_runner.py:110} ERROR - Failed to execute job 160 for task insert_into_table (duplicate key value violates unique constraint "drag_runs_pkey"
DETAIL:  Key (dt, dag_id)=(2024-07-15, Postgres_dag) already exists.
; 2610)
[2024-07-15T16:30:13.965+0000] {local_task_job_runner.py:240} INFO - Task exited with return code 1
[2024-07-15T16:30:14.144+0000] {taskinstance.py:3503} INFO - 0 downstream tasks scheduled from follow-on schedule check
[2024-07-15T16:30:14.207+0000] {local_task_job_runner.py:222} INFO - ::endgroup::
