[2024-07-15T16:24:04.667+0000] {local_task_job_runner.py:120} INFO - ::group::Pre task execution logs
[2024-07-15T16:24:04.858+0000] {taskinstance.py:2076} INFO - Dependencies all met for dep_context=non-requeueable deps ti=<TaskInstance: Postgres_dag.insert_into_table scheduled__2024-07-13T00:00:00+00:00 [queued]>
[2024-07-15T16:24:04.915+0000] {taskinstance.py:2076} INFO - Dependencies all met for dep_context=requeueable deps ti=<TaskInstance: Postgres_dag.insert_into_table scheduled__2024-07-13T00:00:00+00:00 [queued]>
[2024-07-15T16:24:04.916+0000] {taskinstance.py:2306} INFO - Starting attempt 4 of 7
[2024-07-15T16:24:04.998+0000] {taskinstance.py:2330} INFO - Executing <Task(PostgresOperator): insert_into_table> on 2024-07-13 00:00:00+00:00
[2024-07-15T16:24:05.016+0000] {logging_mixin.py:188} WARNING - /home/***/.local/lib/python3.12/site-packages/***/task/task_runner/standard_task_runner.py:61 DeprecationWarning: This process (pid=2090) is multi-threaded, use of fork() may lead to deadlocks in the child.
[2024-07-15T16:24:05.019+0000] {standard_task_runner.py:63} INFO - Started process 2099 to run task
[2024-07-15T16:24:05.018+0000] {standard_task_runner.py:90} INFO - Running: ['***', 'tasks', 'run', 'Postgres_dag', 'insert_into_table', 'scheduled__2024-07-13T00:00:00+00:00', '--job-id', '130', '--raw', '--subdir', 'DAGS_FOLDER/dag_with_postgres.py', '--cfg-path', '/tmp/tmpl64cqvue']
[2024-07-15T16:24:05.023+0000] {standard_task_runner.py:91} INFO - Job 130: Subtask insert_into_table
[2024-07-15T16:24:05.212+0000] {task_command.py:426} INFO - Running <TaskInstance: Postgres_dag.insert_into_table scheduled__2024-07-13T00:00:00+00:00 [running]> on host 32f997017b5a
[2024-07-15T16:24:05.476+0000] {taskinstance.py:2648} INFO - Exporting env vars: AIRFLOW_CTX_DAG_OWNER='Rayzo' AIRFLOW_CTX_DAG_ID='Postgres_dag' AIRFLOW_CTX_TASK_ID='insert_into_table' AIRFLOW_CTX_EXECUTION_DATE='2024-07-13T00:00:00+00:00' AIRFLOW_CTX_TRY_NUMBER='4' AIRFLOW_CTX_DAG_RUN_ID='scheduled__2024-07-13T00:00:00+00:00'
[2024-07-15T16:24:05.477+0000] {taskinstance.py:430} INFO - ::endgroup::
[2024-07-15T16:24:05.517+0000] {sql.py:276} INFO - Executing:  
        insert into drag_runs(dt,dag_id) values('2024-07-13', 'Postgres_dag')
        
[2024-07-15T16:24:05.542+0000] {base.py:84} INFO - Using connection ID 'Postgres_con' for task execution.
[2024-07-15T16:24:05.564+0000] {base.py:84} INFO - Using connection ID 'Postgres_con' for task execution.
[2024-07-15T16:24:05.595+0000] {sql.py:487} INFO - Running statement:  
        insert into drag_runs(dt,dag_id) values('2024-07-13', 'Postgres_dag')
        , parameters: None
[2024-07-15T16:24:05.612+0000] {taskinstance.py:441} INFO - ::group::Post task execution logs
[2024-07-15T16:24:05.613+0000] {taskinstance.py:2905} ERROR - Task failed with exception
Traceback (most recent call last):
  File "/home/airflow/.local/lib/python3.12/site-packages/airflow/models/taskinstance.py", line 465, in _execute_task
    result = _execute_callable(context=context, **execute_callable_kwargs)
             ^^^^^^^^^^^^^^^^^^^^^^^^^^^^^^^^^^^^^^^^^^^^^^^^^^^^^^^^^^^^^
  File "/home/airflow/.local/lib/python3.12/site-packages/airflow/models/taskinstance.py", line 432, in _execute_callable
    return execute_callable(context=context, **execute_callable_kwargs)
           ^^^^^^^^^^^^^^^^^^^^^^^^^^^^^^^^^^^^^^^^^^^^^^^^^^^^^^^^^^^^
  File "/home/airflow/.local/lib/python3.12/site-packages/airflow/models/baseoperator.py", line 401, in wrapper
    return func(self, *args, **kwargs)
           ^^^^^^^^^^^^^^^^^^^^^^^^^^^
  File "/home/airflow/.local/lib/python3.12/site-packages/airflow/providers/common/sql/operators/sql.py", line 282, in execute
    output = hook.run(
             ^^^^^^^^^
  File "/home/airflow/.local/lib/python3.12/site-packages/airflow/providers/common/sql/hooks/sql.py", line 435, in run
    self._run_command(cur, sql_statement, parameters)
  File "/home/airflow/.local/lib/python3.12/site-packages/airflow/providers/common/sql/hooks/sql.py", line 492, in _run_command
    cur.execute(sql_statement)
psycopg2.errors.UniqueViolation: duplicate key value violates unique constraint "drag_runs_pkey"
DETAIL:  Key (dt, dag_id)=(2024-07-13, Postgres_dag) already exists.

[2024-07-15T16:24:05.673+0000] {taskinstance.py:1206} INFO - Marking task as UP_FOR_RETRY. dag_id=Postgres_dag, task_id=insert_into_table, run_id=scheduled__2024-07-13T00:00:00+00:00, execution_date=20240713T000000, start_date=20240715T162404, end_date=20240715T162405
[2024-07-15T16:24:05.805+0000] {standard_task_runner.py:110} ERROR - Failed to execute job 130 for task insert_into_table (duplicate key value violates unique constraint "drag_runs_pkey"
DETAIL:  Key (dt, dag_id)=(2024-07-13, Postgres_dag) already exists.
; 2099)
[2024-07-15T16:24:05.856+0000] {local_task_job_runner.py:240} INFO - Task exited with return code 1
[2024-07-15T16:24:05.965+0000] {taskinstance.py:3503} INFO - 0 downstream tasks scheduled from follow-on schedule check
[2024-07-15T16:24:06.003+0000] {local_task_job_runner.py:222} INFO - ::endgroup::
