[2024-07-15T16:30:14.709+0000] {local_task_job_runner.py:120} INFO - ::group::Pre task execution logs
[2024-07-15T16:30:14.793+0000] {taskinstance.py:2076} INFO - Dependencies all met for dep_context=non-requeueable deps ti=<TaskInstance: Postgres_dag.insert_into_table scheduled__2024-07-13T00:00:00+00:00 [queued]>
[2024-07-15T16:30:14.818+0000] {taskinstance.py:2076} INFO - Dependencies all met for dep_context=requeueable deps ti=<TaskInstance: Postgres_dag.insert_into_table scheduled__2024-07-13T00:00:00+00:00 [queued]>
[2024-07-15T16:30:14.819+0000] {taskinstance.py:2306} INFO - Starting attempt 7 of 7
[2024-07-15T16:30:14.896+0000] {taskinstance.py:2330} INFO - Executing <Task(PostgresOperator): insert_into_table> on 2024-07-13 00:00:00+00:00
[2024-07-15T16:30:14.906+0000] {logging_mixin.py:188} WARNING - /home/***/.local/lib/python3.12/site-packages/***/task/task_runner/standard_task_runner.py:61 DeprecationWarning: This process (pid=2615) is multi-threaded, use of fork() may lead to deadlocks in the child.
[2024-07-15T16:30:14.905+0000] {standard_task_runner.py:90} INFO - Running: ['***', 'tasks', 'run', 'Postgres_dag', 'insert_into_table', 'scheduled__2024-07-13T00:00:00+00:00', '--job-id', '169', '--raw', '--subdir', 'DAGS_FOLDER/dag_with_postgres.py', '--cfg-path', '/tmp/tmp1kpln0rq']
[2024-07-15T16:30:14.909+0000] {standard_task_runner.py:63} INFO - Started process 2622 to run task
[2024-07-15T16:30:14.909+0000] {standard_task_runner.py:91} INFO - Job 169: Subtask insert_into_table
[2024-07-15T16:30:15.048+0000] {task_command.py:426} INFO - Running <TaskInstance: Postgres_dag.insert_into_table scheduled__2024-07-13T00:00:00+00:00 [running]> on host 32f997017b5a
[2024-07-15T16:30:15.243+0000] {taskinstance.py:2648} INFO - Exporting env vars: AIRFLOW_CTX_DAG_OWNER='Rayzo' AIRFLOW_CTX_DAG_ID='Postgres_dag' AIRFLOW_CTX_TASK_ID='insert_into_table' AIRFLOW_CTX_EXECUTION_DATE='2024-07-13T00:00:00+00:00' AIRFLOW_CTX_TRY_NUMBER='7' AIRFLOW_CTX_DAG_RUN_ID='scheduled__2024-07-13T00:00:00+00:00'
[2024-07-15T16:30:15.244+0000] {taskinstance.py:430} INFO - ::endgroup::
[2024-07-15T16:30:15.271+0000] {sql.py:276} INFO - Executing:  
        insert into drag_runs(dt,dag_id) values('2024-07-13', 'Postgres_dag')
        
[2024-07-15T16:30:15.280+0000] {base.py:84} INFO - Using connection ID 'Postgres_con' for task execution.
[2024-07-15T16:30:15.292+0000] {base.py:84} INFO - Using connection ID 'Postgres_con' for task execution.
[2024-07-15T16:30:15.305+0000] {sql.py:487} INFO - Running statement:  
        insert into drag_runs(dt,dag_id) values('2024-07-13', 'Postgres_dag')
        , parameters: None
[2024-07-15T16:30:15.308+0000] {taskinstance.py:441} INFO - ::group::Post task execution logs
[2024-07-15T16:30:15.309+0000] {taskinstance.py:2905} ERROR - Task failed with exception
Traceback (most recent call last):
  File "/home/airflow/.local/lib/python3.12/site-packages/airflow/models/taskinstance.py", line 465, in _execute_task
    result = _execute_callable(context=context, **execute_callable_kwargs)
             ^^^^^^^^^^^^^^^^^^^^^^^^^^^^^^^^^^^^^^^^^^^^^^^^^^^^^^^^^^^^^
  File "/home/airflow/.local/lib/python3.12/site-packages/airflow/models/taskinstance.py", line 432, in _execute_callable
    return execute_callable(context=context, **execute_callable_kwargs)
           ^^^^^^^^^^^^^^^^^^^^^^^^^^^^^^^^^^^^^^^^^^^^^^^^^^^^^^^^^^^^
  File "/home/airflow/.local/lib/python3.12/site-packages/airflow/models/baseoperator.py", line 401, in wrapper
    return func(self, *args, **kwargs)
           ^^^^^^^^^^^^^^^^^^^^^^^^^^^
  File "/home/airflow/.local/lib/python3.12/site-packages/airflow/providers/common/sql/operators/sql.py", line 282, in execute
    output = hook.run(
             ^^^^^^^^^
  File "/home/airflow/.local/lib/python3.12/site-packages/airflow/providers/common/sql/hooks/sql.py", line 435, in run
    self._run_command(cur, sql_statement, parameters)
  File "/home/airflow/.local/lib/python3.12/site-packages/airflow/providers/common/sql/hooks/sql.py", line 492, in _run_command
    cur.execute(sql_statement)
psycopg2.errors.UniqueViolation: duplicate key value violates unique constraint "drag_runs_pkey"
DETAIL:  Key (dt, dag_id)=(2024-07-13, Postgres_dag) already exists.

[2024-07-15T16:30:15.323+0000] {taskinstance.py:1206} INFO - Marking task as FAILED. dag_id=Postgres_dag, task_id=insert_into_table, run_id=scheduled__2024-07-13T00:00:00+00:00, execution_date=20240713T000000, start_date=20240715T163014, end_date=20240715T163015
[2024-07-15T16:30:15.383+0000] {standard_task_runner.py:110} ERROR - Failed to execute job 169 for task insert_into_table (duplicate key value violates unique constraint "drag_runs_pkey"
DETAIL:  Key (dt, dag_id)=(2024-07-13, Postgres_dag) already exists.
; 2622)
[2024-07-15T16:30:15.405+0000] {local_task_job_runner.py:240} INFO - Task exited with return code 1
[2024-07-15T16:30:15.421+0000] {taskinstance.py:3503} INFO - 0 downstream tasks scheduled from follow-on schedule check
[2024-07-15T16:30:15.452+0000] {local_task_job_runner.py:222} INFO - ::endgroup::
