[2024-07-15T16:30:07.387+0000] {local_task_job_runner.py:120} INFO - ::group::Pre task execution logs
[2024-07-15T16:30:07.427+0000] {taskinstance.py:2076} INFO - Dependencies all met for dep_context=non-requeueable deps ti=<TaskInstance: Postgres_dag.insert_into_table manual__2024-07-15T16:02:41.082412+00:00 [queued]>
[2024-07-15T16:30:07.438+0000] {taskinstance.py:2076} INFO - Dependencies all met for dep_context=requeueable deps ti=<TaskInstance: Postgres_dag.insert_into_table manual__2024-07-15T16:02:41.082412+00:00 [queued]>
[2024-07-15T16:30:07.439+0000] {taskinstance.py:2306} INFO - Starting attempt 7 of 7
[2024-07-15T16:30:07.489+0000] {taskinstance.py:2330} INFO - Executing <Task(PostgresOperator): insert_into_table> on 2024-07-15 16:02:41.082412+00:00
[2024-07-15T16:30:07.497+0000] {logging_mixin.py:188} WARNING - /home/***/.local/lib/python3.12/site-packages/***/task/task_runner/standard_task_runner.py:61 DeprecationWarning: This process (pid=2590) is multi-threaded, use of fork() may lead to deadlocks in the child.
[2024-07-15T16:30:07.498+0000] {standard_task_runner.py:63} INFO - Started process 2592 to run task
[2024-07-15T16:30:07.497+0000] {standard_task_runner.py:90} INFO - Running: ['***', 'tasks', 'run', 'Postgres_dag', 'insert_into_table', 'manual__2024-07-15T16:02:41.082412+00:00', '--job-id', '158', '--raw', '--subdir', 'DAGS_FOLDER/dag_with_postgres.py', '--cfg-path', '/tmp/tmp0xlhj6t7']
[2024-07-15T16:30:07.500+0000] {standard_task_runner.py:91} INFO - Job 158: Subtask insert_into_table
[2024-07-15T16:30:07.633+0000] {task_command.py:426} INFO - Running <TaskInstance: Postgres_dag.insert_into_table manual__2024-07-15T16:02:41.082412+00:00 [running]> on host 32f997017b5a
[2024-07-15T16:30:07.750+0000] {taskinstance.py:2648} INFO - Exporting env vars: AIRFLOW_CTX_DAG_OWNER='Rayzo' AIRFLOW_CTX_DAG_ID='Postgres_dag' AIRFLOW_CTX_TASK_ID='insert_into_table' AIRFLOW_CTX_EXECUTION_DATE='2024-07-15T16:02:41.082412+00:00' AIRFLOW_CTX_TRY_NUMBER='7' AIRFLOW_CTX_DAG_RUN_ID='manual__2024-07-15T16:02:41.082412+00:00'
[2024-07-15T16:30:07.752+0000] {taskinstance.py:430} INFO - ::endgroup::
[2024-07-15T16:30:07.774+0000] {sql.py:276} INFO - Executing:  
        insert into drag_runs(dt,dag_id) values('2024-07-15', 'Postgres_dag')
        
[2024-07-15T16:30:07.786+0000] {base.py:84} INFO - Using connection ID 'Postgres_con' for task execution.
[2024-07-15T16:30:07.796+0000] {base.py:84} INFO - Using connection ID 'Postgres_con' for task execution.
[2024-07-15T16:30:07.808+0000] {sql.py:487} INFO - Running statement:  
        insert into drag_runs(dt,dag_id) values('2024-07-15', 'Postgres_dag')
        , parameters: None
[2024-07-15T16:30:07.812+0000] {taskinstance.py:441} INFO - ::group::Post task execution logs
[2024-07-15T16:30:07.813+0000] {taskinstance.py:2905} ERROR - Task failed with exception
Traceback (most recent call last):
  File "/home/airflow/.local/lib/python3.12/site-packages/airflow/models/taskinstance.py", line 465, in _execute_task
    result = _execute_callable(context=context, **execute_callable_kwargs)
             ^^^^^^^^^^^^^^^^^^^^^^^^^^^^^^^^^^^^^^^^^^^^^^^^^^^^^^^^^^^^^
  File "/home/airflow/.local/lib/python3.12/site-packages/airflow/models/taskinstance.py", line 432, in _execute_callable
    return execute_callable(context=context, **execute_callable_kwargs)
           ^^^^^^^^^^^^^^^^^^^^^^^^^^^^^^^^^^^^^^^^^^^^^^^^^^^^^^^^^^^^
  File "/home/airflow/.local/lib/python3.12/site-packages/airflow/models/baseoperator.py", line 401, in wrapper
    return func(self, *args, **kwargs)
           ^^^^^^^^^^^^^^^^^^^^^^^^^^^
  File "/home/airflow/.local/lib/python3.12/site-packages/airflow/providers/common/sql/operators/sql.py", line 282, in execute
    output = hook.run(
             ^^^^^^^^^
  File "/home/airflow/.local/lib/python3.12/site-packages/airflow/providers/common/sql/hooks/sql.py", line 435, in run
    self._run_command(cur, sql_statement, parameters)
  File "/home/airflow/.local/lib/python3.12/site-packages/airflow/providers/common/sql/hooks/sql.py", line 492, in _run_command
    cur.execute(sql_statement)
psycopg2.errors.UniqueViolation: duplicate key value violates unique constraint "drag_runs_pkey"
DETAIL:  Key (dt, dag_id)=(2024-07-15, Postgres_dag) already exists.

[2024-07-15T16:30:07.824+0000] {taskinstance.py:1206} INFO - Marking task as FAILED. dag_id=Postgres_dag, task_id=insert_into_table, run_id=manual__2024-07-15T16:02:41.082412+00:00, execution_date=20240715T160241, start_date=20240715T163007, end_date=20240715T163007
[2024-07-15T16:30:07.873+0000] {standard_task_runner.py:110} ERROR - Failed to execute job 158 for task insert_into_table (duplicate key value violates unique constraint "drag_runs_pkey"
DETAIL:  Key (dt, dag_id)=(2024-07-15, Postgres_dag) already exists.
; 2592)
[2024-07-15T16:30:07.914+0000] {local_task_job_runner.py:240} INFO - Task exited with return code 1
[2024-07-15T16:30:07.936+0000] {taskinstance.py:3503} INFO - 0 downstream tasks scheduled from follow-on schedule check
[2024-07-15T16:30:07.964+0000] {local_task_job_runner.py:222} INFO - ::endgroup::
