[2024-07-15T16:02:11.394+0000] {local_task_job_runner.py:120} INFO - ::group::Pre task execution logs
[2024-07-15T16:02:11.453+0000] {taskinstance.py:2076} INFO - Dependencies all met for dep_context=non-requeueable deps ti=<TaskInstance: Postgres_dag.postgres manual__2024-07-15T16:02:10.248540+00:00 [queued]>
[2024-07-15T16:02:11.465+0000] {taskinstance.py:2076} INFO - Dependencies all met for dep_context=requeueable deps ti=<TaskInstance: Postgres_dag.postgres manual__2024-07-15T16:02:10.248540+00:00 [queued]>
[2024-07-15T16:02:11.466+0000] {taskinstance.py:2306} INFO - Starting attempt 1 of 6
[2024-07-15T16:02:11.739+0000] {taskinstance.py:2330} INFO - Executing <Task(PostgresOperator): postgres> on 2024-07-15 16:02:10.248540+00:00
[2024-07-15T16:02:11.745+0000] {standard_task_runner.py:90} INFO - Running: ['***', 'tasks', 'run', 'Postgres_dag', 'postgres', 'manual__2024-07-15T16:02:10.248540+00:00', '--job-id', '7', '--raw', '--subdir', 'DAGS_FOLDER/dag_with_postgres.py', '--cfg-path', '/tmp/tmpasewhpbv']
[2024-07-15T16:02:11.749+0000] {standard_task_runner.py:91} INFO - Job 7: Subtask postgres
[2024-07-15T16:02:11.750+0000] {logging_mixin.py:188} WARNING - /home/***/.local/lib/python3.12/site-packages/***/task/task_runner/standard_task_runner.py:61 DeprecationWarning: This process (pid=291) is multi-threaded, use of fork() may lead to deadlocks in the child.
[2024-07-15T16:02:11.751+0000] {standard_task_runner.py:63} INFO - Started process 293 to run task
[2024-07-15T16:02:11.905+0000] {task_command.py:426} INFO - Running <TaskInstance: Postgres_dag.postgres manual__2024-07-15T16:02:10.248540+00:00 [running]> on host 32f997017b5a
[2024-07-15T16:02:12.196+0000] {taskinstance.py:2648} INFO - Exporting env vars: AIRFLOW_CTX_DAG_OWNER='Rayzo' AIRFLOW_CTX_DAG_ID='Postgres_dag' AIRFLOW_CTX_TASK_ID='postgres' AIRFLOW_CTX_EXECUTION_DATE='2024-07-15T16:02:10.248540+00:00' AIRFLOW_CTX_TRY_NUMBER='1' AIRFLOW_CTX_DAG_RUN_ID='manual__2024-07-15T16:02:10.248540+00:00'
[2024-07-15T16:02:12.197+0000] {taskinstance.py:430} INFO - ::endgroup::
[2024-07-15T16:02:12.218+0000] {sql.py:276} INFO - Executing:  
        Create table if not exists drag_runs(
        dt date,
        dag_id character varying,
        primary key (dt, dag_id)
        )
        
[2024-07-15T16:02:12.227+0000] {taskinstance.py:441} INFO - ::group::Post task execution logs
[2024-07-15T16:02:12.238+0000] {taskinstance.py:2905} ERROR - Task failed with exception
Traceback (most recent call last):
  File "/home/airflow/.local/lib/python3.12/site-packages/airflow/models/taskinstance.py", line 465, in _execute_task
    result = _execute_callable(context=context, **execute_callable_kwargs)
             ^^^^^^^^^^^^^^^^^^^^^^^^^^^^^^^^^^^^^^^^^^^^^^^^^^^^^^^^^^^^^
  File "/home/airflow/.local/lib/python3.12/site-packages/airflow/models/taskinstance.py", line 432, in _execute_callable
    return execute_callable(context=context, **execute_callable_kwargs)
           ^^^^^^^^^^^^^^^^^^^^^^^^^^^^^^^^^^^^^^^^^^^^^^^^^^^^^^^^^^^^
  File "/home/airflow/.local/lib/python3.12/site-packages/airflow/models/baseoperator.py", line 401, in wrapper
    return func(self, *args, **kwargs)
           ^^^^^^^^^^^^^^^^^^^^^^^^^^^
  File "/home/airflow/.local/lib/python3.12/site-packages/airflow/providers/common/sql/operators/sql.py", line 277, in execute
    hook = self.get_db_hook()
           ^^^^^^^^^^^^^^^^^^
  File "/home/airflow/.local/lib/python3.12/site-packages/airflow/providers/common/sql/operators/sql.py", line 188, in get_db_hook
    return self._hook
           ^^^^^^^^^^
  File "/usr/local/lib/python3.12/functools.py", line 995, in __get__
    val = self.func(instance)
          ^^^^^^^^^^^^^^^^^^^
  File "/home/airflow/.local/lib/python3.12/site-packages/airflow/providers/common/sql/operators/sql.py", line 150, in _hook
    conn = BaseHook.get_connection(conn_id)
           ^^^^^^^^^^^^^^^^^^^^^^^^^^^^^^^^
  File "/home/airflow/.local/lib/python3.12/site-packages/airflow/hooks/base.py", line 83, in get_connection
    conn = Connection.get_connection_from_secrets(conn_id)
           ^^^^^^^^^^^^^^^^^^^^^^^^^^^^^^^^^^^^^^^^^^^^^^^
  File "/home/airflow/.local/lib/python3.12/site-packages/airflow/models/connection.py", line 519, in get_connection_from_secrets
    raise AirflowNotFoundException(f"The conn_id `{conn_id}` isn't defined")
airflow.exceptions.AirflowNotFoundException: The conn_id `postgre_local` isn't defined
[2024-07-15T16:02:12.244+0000] {taskinstance.py:1206} INFO - Marking task as UP_FOR_RETRY. dag_id=Postgres_dag, task_id=postgres, run_id=manual__2024-07-15T16:02:10.248540+00:00, execution_date=20240715T160210, start_date=20240715T160211, end_date=20240715T160212
[2024-07-15T16:02:12.367+0000] {standard_task_runner.py:110} ERROR - Failed to execute job 7 for task postgres (The conn_id `postgre_local` isn't defined; 293)
[2024-07-15T16:02:12.408+0000] {local_task_job_runner.py:240} INFO - Task exited with return code 1
[2024-07-15T16:02:12.430+0000] {taskinstance.py:3503} INFO - 0 downstream tasks scheduled from follow-on schedule check
[2024-07-15T16:02:12.469+0000] {local_task_job_runner.py:222} INFO - ::endgroup::
